Workbook
Name Català: #REF!
Name Castellà: #REF!
Name Castellà: #REF!
Name Català: 'COMPETÈNCIES OCULT'!$G$4:$G$13
Name Català: #REF!
Name Català: #REF!
Name Castellà: #REF!
Name Castellà: #REF!

Sheet PORTADA
C20: Programació basada en la plantilla del Departament d'Educació. (amb les competències transversals incloses)
B22: EDUCACIÓ SECUNDÀRIA (ESO) | C22: 1- Feu-vos una còpia del fitxer al vostre drive (Fitxer / Fes una còpia)
C24: 2- Moveu-vos pel fitxer amb els botons de la dreta (el primer cop que els cliqueu us demanarà permís per fer-ho) o amb les pestanyes inferiors.
C26: 3 - Per imprimir trieu l'opció "Llibre de treball" perquè s'imprimeixin tots els apartats.
C28: 4- Si afegiu recursos o milloreu qualsevol cosa, us agrairem que ens ho compartiu (tortiz@xtec.cat i amarsal3@xtec.cat)
B31: Ompliu en aquest ordre: Cicle / Curs / Matèria a INICI
B32: Aquesta tria determinarà el contingut dels desplegables dels altres apartats.
B33: Darrera actualització: Setembre 2023
B34: Propietat intelectual: Reconeixement - NoComercial - CompartirIgual (by-nc-sa) o CC by-nc-sa: No es permet un ús comercial de l'obra original ni de les possibles obres derivades, la distribució de les quals s'ha de fer amb una llicència igual a la que regula l'obra original

Sheet COMPETÈNCIES OCULT
C1: Obligatòries 1r - 4t | O1: A cada curs (1r a 3r) s'ha d'oferir com a mínim una de les dues | S1: A cada curs (1r a 3r) s'ha d'oferir com a mínim una de les dues | W1: Obligatòria en algun dels cursos de 1r a 3r | AA1: Obligatòria 4t ESO | AC1: Optatives 4t | AE1: Optatives 4t | AG1: Optatives 4t | AI1: Optatives 4t | AK1: Optatives 4t | AM1: Optatives 4t | AO1: Optatives 4t | AQ1: Optatives 4t | AS1: Optatives 4t | AU1: Optatives 4t | AW1: Optatives 4t | AY1: Optatives 4t | BA1: COMPETÈNCIES TRANSVERSALS
C3: Llengua Catalana i Literatura | E3: Llengua Castellana i Literatura | G3: Llengua Estrangera | I3: Ciències Socials: Geografia i Història | K3: Educació Física | M3: Matemàtiques | O3: Biologia i Geologia | Q3: Física i Química | S3: Música | U3: Educació Plàstica, Visual i Audiovisual | W3: Tecnologia i Digitalització | X3: Robòtica i Programació | Y3: Cultura Clàssica | AA3: Educació en Valors Cívics i Ètics | AC3: Arts Escèniques i Dansa | AE3: Biologia i Geologia | AG3: Digitalització | AI3: Economia Bàsica | AK3: Emprenedoria | AM3: Filosofia | AO3: Física i Química | AQ3: Formació i Orientació Personal i Professional | AS3: Llatí: Llengua i Cultura | AU3: Música | AW3: Segona Llengua Estrangera | AY3: Tecnologia | BA3: Competència Ciutadana | BB3: Competència Emprenedora | BC3: Competència Digital | BD3: CPSAA
B4: COMPETÈNCIES ESPECÍFIQUES | C4: 1. Descriure i valorar la diversitat lingüística i cultural a partir del reconeixement de les llengües de l’alumnat i la realitat plurilingüe i pluricultural, per afavorir la transferència lingüística, identificar i rebutjar estereotips i prejudicis lingüístics, i valorar aquesta diversitat com a font de riquesa cultural. | E4: 1. Descriure i valorar la diversitat lingüística i cultural a partir del reconeixement de les llengües de l’alumnat i la realitat plurilingüe i pluricultural, per afavorir la transferència lingüística, identificar i rebutjar estereotips i prejudicis lingüístics, i valorar aquesta diversitat com a font de riquesa cultural. | G4: 1. Descriure i valorar la diversitat lingüística i cultural a partir del reconeixement de les llengües de l’alumnat i la realitat plurilingüe, pluricultural i intercultural, per afavorir la transferència lingüística, identificar i rebutjar estereotips i prejudicis lingüístics i valorar aquesta diversitat com a font de riquesa cultural. | I4: 1. Cercar i tractar informació que permeti interpretar el present i el passat, aplicant els procediments de la recerca històrica i geogràfica a partir de l’anàlisi crítica de dades procedents de fonts analògiques i digitals, per transformar-ho en coneixement i comunicar-ho a través de diferents formats. | K4: 1. Adquirir un estil de vida actiu i saludable incorporant la pràctica d’activitats físiques i d’hàbits beneficiosos per a la contribució del benestar físic, mental i social. | M4: 1. Interpretar, modelitzar i resoldre situacions de la vida quotidiana, pròpies de les matemàtiques i d’altres àmbits del coneixement aplicant diferents estratègies i formes de raonament per explorar procediments i obtenir solucions. | O4: 1. Interpretar fenómens de la naturalesa, predient i argumentant el seu comportament a partir de models, lleis i teories propis de la biologia i la geologia per apropiar-se de conceptes i processos propis de la ciència. | Q4: 1. Interpretar fenòmens de la naturalesa, predient i argumentant-ne el comportament a partir de models, lleis i teories propis de la física i química per apropiar-se de conceptes i processos propis de la ciència. | S4: 1. Analitzar produccions musicals a través de l’escolta activa, la identificació d’elements i la reflexió per entendre’n l’evolució i funcions dins la cultura. | U4: 1. Descobrir les manifestacions artístiques contemporànies i del patrimoni cultural, interessant-se per la realitat patrimonial com a part de la pròpia cultura, per reconèixer-les com a testimoni del pensament i com a font d’aprenentatge, prenent consciència de la necessitat de conservar-les. | W4: 1. Buscar, analitzar i seleccionar la informació adequada, de manera crítica i segura, tot aplicant processos de recerca, mètodes d’anàlisi de productes i experimentant amb eines de simulació, per delimitar problemes tecnològics i proposar solucions a partir de la informació obtinguda. | X4: 1. Dissenyar prototips creatius i funcionals per respondre a problemes i reptes concrets a partir de projectes col·laboratius, utilitzant tècniques de pensament de disseny. | Y4: 1.Analitzar i diferenciar els diferents models d’organització política, social, econòmica i territorial del període grecoromà amb el moment històric present per ser conscient de les arrels clàssiques del món actual. | AA4: 1. Indagar i analitzar aspectes vinculats a la construcció de la pròpia identitat i a les qüestions ètiques relatives al projecte vital, en un context social, analitzant de forma reflexiva i crítica la informació obtinguda, per promoure l’autoconeixement i la resolució de dilemes morals de forma autònoma i raonada. | AC4: 1. Analitzar produccions d’arts escèniques i dansa a través de la identificació d’elements i la reflexió per entendre’n l’evolució i les funcions dins la cultura. | AE4: 1. Interpretar fenómens de la naturalesa, predient i argumentant el seu comportament a partir de models, lleis i teories propis de la biologia i la geologia per apropiar-se de conceptes i processos propis de la ciència. | AG4: 1. Gestionar les eines i els dispositius informàtics i de comunicació d’ús quotidià aplicant els coneixements de maquinari i sistemes operatius per resoldre problemes tècnics senzills. | AI4: 1. Reconèixer els rols individuals i col·lectius de les persones dintre del sistema econòmic i constituir dinàmiques de participació ciutadana, prenent consciència de la interdependència dels factors econòmics, per valorar les desigualtats en l’accés als recursos i la distribució de la riquesa. | AK4: 1. Analitzar i valorar aptituds, reconeixent les fortaleses i debilitats pròpies i dels altres, gestionant de forma eficaç les emocions i destreses necessàries per promoure una actitud vital emprenedora davant entorns incerts, canviants i globalitzats, amb la creació d’un projecte personal que generi valor per als altres. | AM4: 1. Identificar i valorar l’especificitat del saber filosòfic i dels sabers que aporten certesa enfront d’altres tipus de saber, per tal d’avaluar críticament els discursos i arguments. | AO4: 1. Interpretar fenòmens de la naturalesa, predient i argumentant-ne el comportament a partir de models, lleis i teories propis de la física i química per apropiar-se de conceptes i processos propis de la ciència. | AQ4: 1. Integrar els processos físics i psicològics implicats en la cognició, la motivació i l’aprenentatge, analitzant-ne les implicacions en la conducta per desenvolupar estratègies de gestió emocional i d’autoaprenentatge en els àmbits personal, social i acadèmic. | AS4: 1. Valorar i argumentar el paper de la civilització llatina en l’origen de la identitat catalana i europea en general a partir del reconeixement de les semblances i diferències entre llengües i cultures, per combatre els estereotips i prejudicis lingüístics i culturals, i valorar aquesta diversitat com a font de riquesa cultural. | AU4: 1. Analitzar produccions musicals a través de l’escolta activa, la identificació d’elements i la reflexió per entendre’n l’evolució i funcions dins la cultura. | AW4: 1. Descriure i valorar la diversitat lingüística i cultural a partir del reconeixement de les llengües de l’alumnat i la realitat plurilingüe, pluricultural i intercultural, per afavorir la transferència lingüística, identificar i rebutjar estereotips i prejudicis lingüístics i valorar aquesta diversitat com a font de riquesa cultural. | AY4: 1. Identificar i proposar problemes tecnològics amb iniciativa i creativitat, tot estudiant les necessitats de l’entorn proper, aplicant estratègies i processos col·laboratius i iteratius relatius a projectes, per idear i planificar solucions de manera eficient i innovadora. | BA4: CC1. Analitzar i comprendre idees relatives a la dimensió social i ciutadana de la seva pròpia identitat, així com als fets socials, històrics i normatius que la determinen, demostrant respecte per les normes, empatia, equitat i esperit constructiu en la interacció amb els altres en diferents contextos socioinstitucionals. | BB4: CE1. Analitzar necessitats i oportunitats i afrontar reptes amb sentit crític, fent balanç de la seva sostenibilitat i valorant l’impacte que puguin suposar en l’entorn, per presentar idees i solucions innovadores, ètiques i sostenibles dirigides a crear valor en l’àmbit personal, social, cultural i econòmic. | BC4: CD1. Fer cerques avançades a Internet atenent a criteris de validesa, qualitat, actualitat i fiabilitat, seleccionant-les de manera crítica i arxivant-les per recuperar, referenciar i reutilitzar aquestes recerques respecte a la propietat intel·lectual. | BD4: CPSAA 1. Regular i expressar les seves emocions enfortint l’optimisme, la resiliència, l’autoeficàcia i la recerca de propòsit i motivació cap a l’aprenentatge per gestionar els reptes i canvis i harmonitzar-los amb els seus propis objectius.
C5: 2. Comprendre i interpretar textos orals i multimodals recollint el sentit general i la informació més rellevant, la seva forma i el seu contingut, per construir coneixement, formar-se opinió i eixamplar les possibilitats de gaudi i lleure. | E5: 2. Comprendre i interpretar textos orals i multimodals recollint el sentit general i la informació més rellevant, la seva forma i el seu contingut, per construir coneixement, formar-se opinió i eixamplar les possibilitats de gaudi i lleure. | G5: 2. Comprendre i interpretar textos orals i multimodals, en la llengua estàndard, recollint el sentit general i la informació més rellevant, la seva forma i el seu contingut, per construir coneixement, formar-se opinió i eixamplar les possibilitats de gaudi i lleure. | I5: 2. Indagar i argumentar a partir de problemes socials rellevants, locals i globals, per desenvolupar un pensament crític i respectuós amb les diferències, que contribueixi a la construcció de la identitat individual i col·lectiva i a la consecució d’un present i un futur més just i inclusiu. | K5: 2. Aplicar la tècnica, la tàctica i l’estratègia vinculades amb els jocs i els esports per a la resolució de situacions motrius. | M5: 2. Argumentar la idoneïtat de les solucions d’un problema, avaluant les respostes obtingudes a través del raonament i la lògica matemàtica, per verificar la seva validesa i generar noves preguntes i reptes. | O5: 2. Identificar, seleccionar, organitzar i avaluar críticament dades i informació, contrastant-ne la fiabilitat per resoldre preguntes relacionades amb la biologia i la geologia i descartar solucions pseudocientífiques. | Q5: 2. Dissenyar, desenvolupar i comunicar el plantejament i les conclusions de recerques incloent la formulació de preguntes i d’hipòtesis i la seva contrastació experimental, dins de l’àmbit escolar, seguint els passos de les metodologies pròpies de la ciència, com l’experimentació i la cerca d'evidències, i del pensament computacional cooperant, quan calgui, per indagar en aspectes relacionats amb la física i la química. | S5: 2. Expressar-se musicalment a través d’improvisacions vocals o instrumentals tenint en compte les emocions que provoquen i per desenvolupar la creativitat amb una actitud col·laborativa. | U5: 2. Analitzar produccions artístiques, pròpies i alienes, argumentant opinions amb respecte i sentit crític, per construir una cultura artística àmplia, gaudir i generar nous coneixements. | W5: 2. Planificar, dissenyar i desenvolupar solucions a problemes tecnològics amb autonomia i actitud creativa, tot aplicant el procés tecnològic, coneixements interdisciplinaris i treballant de manera ordenada i cooperativa, per resoldre problemes o necessitats de manera eficaç, innovadora i sostenible. | X5: 2. Aplicar estratègies de pensament computacional de manera organitzada i òptima per crear, reelaborar o millorar algoritmes que ajudin a resoldre problemes reals. | Y5: 2. Analitzar i avaluar críticament les cosmovisions que contenen les manifestacions culturals grecoromanes amb l’objectiu d’establir vincles amb les manifestacions culturals actuals, fent ús d’eines digitals per a la cerca i el tractament de la informació. | AA5: 2. Integrar de forma crítica normes i valors cívics i ètics i actuar i interactuar, a partir del reconeixement de la seva importància en la regulació de la vida individual i comunitària, per aplicar-los de forma efectiva i justificada en diferents contextos i per promoure una convivència pacífica, respectuosa, democràtica i compromesa amb el bé comú i una societat inclusiva. | AC5: 2. Expressar-se a través d’improvisacions escèniques i de moviment tenint en compte les emocions que provoquen per desenvolupar la creativitat amb una actitud col-laborativa. | AE5: 2. Identificar, seleccionar, organitzar i avaluar críticament dades i informació, contrastant-ne la fiabilitat per resoldre preguntes relacionades amb la biologia i la geologia i descartar solucions pseudocientífiques. | AG5: 2. Idear solucions innovadores i creatives aplicant diferents formes de raonament, integrant-les en l’entorn personal d’aprenentatge tot fent ús de les eines i els recursos d’edició, la creació de continguts digitals i el desenvolupament d’aplicacions per optimitzar l’aprenentatge permanent. | AI5: 2. Integrar i promoure pràctiques econòmiques basades en valors humans, solidaris i sostenibles, amb consciència ciutadana, per contribuir a una societat més equitativa, justa i sostenible en un món global i divers. | AK5: 2. Col·laborar eficaçment amb altres persones i constituir dinàmiques de treball en diferents contextos, utilitzant estratègies de formació d’equips des del diàleg, l’equitat, el respecte a la diversitat i la inclusió per desenvolupar idees emprenedores. | AM5: 2. Avaluar i generar arguments per valorar i produir discursos orals i escrits de forma rigorosa, evitar dogmatismes, biaixos i fal·làcies, per tal de desenvolupar i sostenir opinions. | AO5: 2. Dissenyar, desenvolupar i comunicar el plantejament i les conclusions de recerques incloent la formulació de preguntes i d’hipòtesis i la seva contrastació experimental, dins de l’àmbit escolar, seguint els passos de les metodologies pròpies de la ciència, com l’experimentació i la cerca d'evidències, i del pensament computacional cooperant, quan calgui, per indagar en aspectes relacionats amb la física i la química. | AQ5: 2. Identificar les principals característiques del desenvolupament evolutiu de la persona, analitzant els elements que condicionen la conducta i potenciant les qualitats personals i de relació social pròpies i dels altres, per afrontar de forma autònoma i eficaç els reptes de l’itinerari vital. | AS5: 2. Analitzar i percebre els aspectes bàsics de la llengua llatina, comparant-la amb la llengua d’ensenyament i amb altres llengües del repertori individual de l’alumnat, per valorar els trets comuns i la diversitat lingüística. | AU5: 2. Expressar-se musicalment a través d’improvisacions vocals o instrumentals tenint en compte les emocions que provoquen i per desenvolupar la creativitat amb una actitud col·laborativa. | AW5: 2. Comprendre i interpretar textos orals i multimodals, en la llengua estàndard, recollint el sentit general i la informació més rellevant, la seva forma i el seu contingut, per construir coneixement, formar-se opinió i eixamplar les possibilitats de gaudi i lleure. | AY5: 2. Aplicar diferents tècniques i coneixements interdisciplinaris utilitzant procediments i recursos tecnològics tot preveient el cicle de vida dels productes per construir solucions tecnològiques sostenibles que donin resposta a necessitats plantejades. | BA5: CC2. Analitzar i assumir amb fonament els principis i valors que demanen del procés d’integració europeu, de l’ordenament jurídic de l’Estat espanyol i de Catalunya i dels drets humans i de l’infant, participant en activitats comunitàries, com la presa de decisions o la resolució de conflictes, amb actitud democràtica, respecte per la diversitat, i compromís amb la igualtat de gènere, la cohesió social, el desenvolupament sostenible i l’assoliment de la ciutadania mundial. | BB5: CE2. Avaluar les fortaleses i debilitats pròpies fent ús d’estratègies d’autoconeixement i autoeficàcia, comprendre els elements fonamentals de l’economia i les finances i aplicar coneixements econòmics i financers a activitats i situacions concretes, utilitzant habilitats que afavoreixin el treball col·laboratiu i en equip, per reunir i optimitzar els recursos necessaris que portin a l’acció una experiència emprenedora de valor. | BC5: CD2. Gestionar i utilitzar el propi entorn personal digital d’aprenentatge permanent per construir nou coneixement i crear continguts digitals, mitjançant estratègies de tractament de la informació i l’ús de diferents eines digitals, seleccionant i configurant la més adequada en funció de la tasca i de les necessitats en cada ocasió. | BD5: CPSAA 2. Conèixer els riscos per a la salut relacionats amb factors socials, per consolidar hàbits de vida saludable en el terreny físic i mental.
C6: 3. Produir textos orals i multimodals amb coherència, claredat i registre adequats, atenent les convencions pròpies dels diferents gèneres discursius i participar en interaccions orals variades, amb autonomia, per expressar idees, sentiments i conceptes, construir coneixement i establir vincles personals. | E6: 3. Produir textos orals i multimodals amb coherència, claredat i registre adequats, atenent les convencions pròpies dels diferents gèneres discursius i participar en interaccions orals variades, amb autonomia, per expressar idees, sentiments i conceptes, construir coneixement i establir vincles personals. | G6: 3. Produir textos orals i multimodals amb coherència, claredat i registre adequats, atenent les convencions própies dels diferents gèneres discursius, i participar en interaccions orals variades, amb autonomia, per expressar idees, sentiments i conceptes, construir coneixement i establir vincles personals. | I6: 3. Interpretar els canvis i les continuïtats dels processos històrics, mitjançant la realització de projectes d’investigació i l’ús de fonts primàries i secundàries, per interpretar els problemes del món actual i fer propostes a favor de la pau, el benestar i el desenvolupament sostenible. | K6: 3. Utilitzar els recursos expressius com a mitjà de relació, comunicació i integració social per a l’autoconeixement. | M6: 3. Formular conjectures senzilles o problemes, utilitzant el raonament i l’argumentació, la creativitat i les eines tecnològiques, per integrar i generar nou coneixement matemàtic. | O6: 3. Dissenyar, desenvolupar i comunicar el plantejament i les conclusions de recerques dins de l’àmbit escolar, incloent la formulació de preguntes i d’hipótesis i la seva contrastació experimental, seguint els passos de les metodologies própies de la ciència, com l’experimentació i la cerca d’evidències, cooperant quan calgui, per indagar en aspectes relacionats amb la biologia i la geologia. | Q6: 3. Generar, interpretar i validar dades i informació en diferents formats i fonts, fent servir de manera adient el llenguatge científic específic de la física i la química, i usar de manera responsable i segura el material de laboratori, per valorar el llenguatge científic com a eina universal de comunicació i intercanvi de coneixement. | S6: 3. Interpretar a través de la veu, els instruments i la dansa per explorar les possibilitats creatives, expressives i emocionals i desenvolupar l’autoestima. | U6: 3. Representar idees, formes i emocions, utilitzant els llenguatges, les tècniques i els mitjans propis de l’àmbit, a través de processos analítics i creatius, per desenvolupar la imaginació, la comunicació i l’autoconfiança. | W6: 3. Aplicar de manera apropiada diferents tècniques i coneixements interdisciplinaris, tot utilitzant operadors, sistemes tecnològics i eines, seguint la planificació i el disseny sostenible previ per construir solucions tecnològiques que donin resposta a necessitats en diferents contextos. | X6: 3. Configurar i programar plaques de prototipatge programables i sensors i actuadors que permetin donar resposta als reptes o problemes, fent servir estructures lògiques a partir de llenguatges de programació. | Y6: 3. Valorar i argumentar el patrimoni cultural grecoromà com a herència rebuda del passat, per defensar-ne la conservació. | AA6: 3. Integrar i avaluar les relacions sistèmiques entre l’individu, la societat i la natura i l’ecodependència de les activitats humanes, mitjançant la identificació i l’anàlisi de problemes ecosocials de rellevància, per desenvolupar hàbits i actituds èticament compromeses amb l’assoliment d’un estil de vida sostenible. | AC6: 3. Interpretar a través de la veu i/o el cos per explorar les possibilitats creatives, expressives i emocionals i desenvolupar l’autoestima. | AE6: 3. Dissenyar, desenvolupar i comunicar el plantejament i les conclusions de recerques dins de l’àmbit escolar, incloent la formulació de preguntes i d’hipótesis i la seva contrastació experimental, seguint els passos de les metodologies própies de la ciència, com l’experimentació i la cerca d’evidències, cooperant quan calgui, per indagar en aspectes relacionats amb la biologia i la geologia. | AG6: 3. Identificar riscos i amenaces i aplicar mesures preventives i correctives, adquirint hàbits que fomentin el benestar digital per protegir dispositius, dades personals i la pròpia salut. | AI6: 3. Analitzar i contrastar informació de diferents fonts i suports, a través de mètodes de recerca, amb rigor i sentit crític, per suggerir mesures econòmiques que millorin l’entorn social i el medi ambient. | AK6: 3. Promoure actuacions locals i globals compromeses amb la societat i l’entorn, amb visió creativa, emprenedora i compromesa per contribuir al desenvolupament sostenible. | AM6: 3. Reconèixer i aplicar les normes de l’argumentació i del diàleg filosòfic, en diferents suports i activitats, per expressar-se amb rigor argumentatiu i desenvolupar el diàleg respectuós i constructiu amb els altres i poder arribar a idees comunes. | AO6: 3. Generar, interpretar i validar dades i informació en diferents formats i fonts, fent servir de manera adient el llenguatge científic específic de la física i la química, i usar de manera responsable i segura el material de laboratori, per valorar el llenguatge científic com a eina universal de comunicació i intercanvi de coneixement. | AQ6: 3. Reflexionar sobre l’ésser humà, des de diferents perspectives -psicològica, antropològica i social-, mostrant els trets diferencials de forma respectuosa i empàtica per fomentar l’esperit crític envers els altres i l’entorn, i promoure el compromís d’un desenvolupament sostenible en la societat. | AS6: 3. Interpretar i valorar, amb sentit crític i diferents propòsits de lectura, textos llatins, reconeixent el sentit global i les idees principals i secundàries, assumint l’aproximació als textos com un procés dinàmic i prenent consciència dels coneixements i experiències pròpies, per identificar el seu caràcter clàssic i fonamental. | AU6: 3. Interpretar a través de la veu, els instruments i la dansa per explorar les possibilitats creatives, expressives i emocionals i desenvolupar l’autoestima. | AW6: 3. Produir textos orals i multimodals amb coherència, claredat i registre adequats, atenent les convencions própies dels diferents gèneres discursius, i participar en interaccions orals variades, amb autonomia, per expressar idees, sentiments i conceptes, construir coneixement i establir vincles personals. | AY6: 3. Comunicar, argumentar i difondre idees i solucions tecnològiques en diferents espais virtuals, emprant diversos recursos tot aplicant els elements i les tècniques necessàries per intercanviar la informació i fomentar el treball en equip. | BA6: CC3. Analitzar i comprendre problemes ètics fonamentals i d’actualitat, considerant críticament els valors propis i aliens, i desenvolupant els seus propis judicis per afrontar la controvèrsia moral amb actitud dialogant, argumentativa, respectuosa i oposada a qualsevol tipus de discriminació o violència —incloent-hi la violència masclista, LGTBI- fòbica, racista o capacitista— o fonamentalisme ideològic. | BB6: CE3. Desenvolupar el procés de creació d’idees i solucions valuoses i prendre decisions, de manera raonada, utilitzant estratègies àgils de planificació i gestió i reflexionant sobre el procés realitzat i el resultat obtingut, per dur a terme el procés de creació de prototips innovadors i de valor, considerant l’experiència com una oportunitat per aprendre. | BC6: CD3. Participar, col·laborar i interactuar mitjançant eines o plataformes virtuals per comunicar-se, treballar col·laborativament i compartir continguts, dades i informació, gestionant de manera responsable les pròpies accions, presència i visibilitat a la xarxa i exercint una ciutadania digital activa, cívica i reflexiva. | BD6: CPSAA 3. Comprendre proactivament les perspectives i les experiències dels altres i incorporar-les al seu aprenentatge per participar en el treball en grup distribuint i acceptant tasques i responsabilitats de manera equitativa i emprant estratègies cooperatives.
C7: 4. Comprendre, interpretar i analitzar, amb sentit crític i diferents propòsits de lectura, textos escrits i multimodals reconeixent-ne el sentit global i les idees principals i secundàries, identificant-ne la intenció de l’emissor, reflexionant-ne sobre el contingut i la forma i avaluar-ne la qualitat i fiabilitat, per tal de construir coneixement i donar resposta a necessitats i interessos comunicatius diversos. | E7: 4. Comprendre, interpretar i analitzar, amb sentit crític i diferents propòsits de lectura, textos escrits i multimodals reconeixent-ne el sentit global i les idees principals i secundàries, identificant-ne la intenció de l’emissor, reflexionant-ne sobre el contingut i la forma i avaluar-ne la qualitat i fiabilitat, per tal de construir coneixement i donar resposta a necessitats i interessos comunicatius diversos. | G7: 4. Comprendre, interpretar i analitzar, amb sentit crític i diferents propósits de lectura, textos escrits i multimodals reconeixent el sentit global i les idees principals i secundàries, identificant la intenció de l’emissor, reflexionant sobre el contingut i la forma i avaluant-ne la qualitat i fiabilitat, per tal de construir coneixement i donar resposta a necessitats i interessos comunicatius diversos. | I7: 4. Descobrir i analitzar els elements i dinàmiques que configuren el territori, mitjançant l’estudi de casos i problemàtiques geogràfiques, per valorar els diferents paisatges i proposar alternatives de gestió territorial, amb criteris de sostenibilitat i justícia social. | K7: 4. Planificar activitats físiques a l’entorn de manera sostenible i segura per a l’ocupació i gaudi del temps de lleure. | M7: 4. Utilitzar el pensament computacional, organitzant dades, descomponent en parts, reconeixement patrons, interpretant, modificant, generalitzant i creant algoritmes per modelitzar situacions i resoldre problemes de forma eficient. | O7: 4. Fer servir diverses formes de raonament, com el pensament hipoteticodeductiu i el pensament computacional, per resoldre problemes o donar explicació a fenómens naturals i processos de la vida quotidiana relacionats amb la biologia i la geologia, mitjancant l’anàlisi crítica de les respostes i solucions i reformulant el procediment, si fos necessari. | Q7: 4. Utilitzar de forma crítica i eficient plataformes tecnològiques i recursos variats, tant per al treball individual com en equip, per a la cerca d’informació, la creació de materials i la comunicació fonamentada en coneixements de la física i la química, entorn de fenòmens i qüestions ecosocialment rellevants. | S7: 4. Crear projectes musicals a través de la veu, els instruments i el cos amb el suport de les eines tecnològiques per desenvolupar oportunitats personals, socials i professionals de forma inclusiva. | U7: 4. Connectar idees i coneixements, aplicant-los, donant nous sentits, en projectes artístics de contextos diversos per fomentar una mirada creativa multidimensional. | W7: 4. Descriure, representar i intercanviar idees o solucions a problemes tecnològics o digitals, utilitzant els mitjans de representació, simbologia i vocabulari adequats, així com els instruments i els recursos disponibles, utilitzant les eines digitals per argumentar, comunicar i difondre informació. | X7: 4. Construir estructures i mecanismes per respondre als requeriments mecànics necessaris, a partir de components específics o dissenyats i produïts mitjançant la utilització d’eines de disseny digital. | Y7: 4. Percebre i valorar com a llengües originàries la llengua grega i la llengua llatina i conèixer els principals autors i autores de la seva literatura, per ser conscient de l’estreta dependència de les llengües i literatures actuals respecte dels seus referents grecoromans. | AA7: 4. Desenvolupar i mostrar una adequada estima de si mateix i de l’entorn, reconeixent i valorant les emocions i els sentiments propis i aliens, per a l’assoliment d’una actitud empàtica, respectuosa i acurada envers un mateix, els altres i la natura. | AC7: 4. Crear projectes escènics i de moviment a través de la veu, el cos, els objectes i l’espai escènic amb el suport de les eines tecnológiques per desenvolupar oportunitats personals, socials i professionals de forma inclusiva. | AE7: 4. Fer servir diverses formes de raonament, com el pensament hipoteticodeductiu i el pensament computacional, per resoldre problemes o donar explicació a fenómens naturals i processos de la vida quotidiana relacionats amb la biologia i la geologia, mitjancant l’anàlisi crítica de les respostes i solucions i reformulant el procediment, si fos necessari. | AG7: 4. Fer un ús actiu, responsable i ètic de les tecnologies digitals, valorant les possibles accions que cal fer a la xarxa i identificar-ne les repercussions per exercir una ciutadania digital crítica. | AI7: 4. Reconèixer el funcionament bàsic del sistema financer i els instruments de política fiscal del sector públic, coneixent les fonts financeres i aplicant la tria d’aquestes per prendre decisions sobre estalvi i inversió, i per regular l’activitat econòmica amb criteris ètics i de sostenibilitat. | AK7: 4. Analitzar i contrastar informació de diferents fonts i suports, a través de mètodes de recerca, amb rigor i sentit crític, per detectar necessitats i oportunitats en un món global i divers. | AM7: 4. Avaluar de manera global, sistèmica i transdisciplinària els problemes ètics i polítics fonamentals i d’actualitat analitzant-los filosòficament per a poder tractar-les de manera creativa i prendre una posició. | AO7: 4. Utilitzar de forma crítica i eficient plataformes tecnològiques i recursos variats, tant per al treball individual com en equip, per a la cerca d’informació, la creació de materials i la comunicació fonamentada en coneixements de la física i la química, entorn de fenòmens i qüestions ecosocialment rellevants. | AQ7: 4. Integrar la dimensió social i antropològica de l’ésser humà, considerant els factors personals i socioculturals que intervenen en la configuració psicològica de la persona, per desenvolupar, de forma inclusiva, les estratègies i habilitats socials necessàries en l’adaptació als canvis de la societat. | AS7: 4. Interpretar i crear produccions llatines (escrites o orals) de tipologia diversa i estructura morfosintàctica senzilla, aplicant estratègies de planificació, redacció, revisió, correcció i edició, i mobilitzant el coneixement sobre l’estructura de la llengua per promoure una capacitat àgil de raonament i aprenentatge. | AU7: 4. Crear projectes musicals a través de la veu, els instruments i el cos amb el suport de les eines tecnológiques per desenvolupar oportunitats personals, socials i professionals de forma inclusiva. | AW7: 4. Comprendre i interpretar textos escrits i multimodals, reconeixent-ne el sentit global, les idees principals i la informació implícita i explícita, i realitzant, de manera progressivament autónoma, reflexions elementals sobre aspectes formals i de contingut, per adquirir i construir coneixement, i respondre a necessitats i interessos comunicatius diversos. | AY7: 4. Desenvolupar solucions sostenibles a problemes plantejats que incorporin l’automatització i les tecnologies emergents, per dissenyar i construir sistemes de control programables i robòtics. | BA7: CC4. Interpretar les relacions sistèmiques d’interdependència, ecodependència i interconnexió entre actuacions locals i globals i adoptar, conscientment i motivadament, un estil de vida sostenible i ecosocialment responsable. | BC7: CD4. Identificar riscos i adoptar mesures en l’ús de les tecnologies digitals per protegir els dispositius, les dades personals, la salut i el medi ambient i per prendre consciència de la importància i necessitat de fer un ús crític, legal, segur, saludable i sostenible d’aquestes tecnologies. | BD7: CPSAA 4. Fer autoavaluacions sobre el propi procés d’aprenentatge, buscant fonts fiables per validar, sustentar i contrastar la informació i per obtenir conclusions rellevants.
C8: 5. Produir textos escrits i multimodals amb adequació, coherència, cohesió, aplicant estratègies elementals de planificació, redacció, revisió, correcció i edició, amb regulació dels iguals i autoregulació progressivament autónoma i atenent les convencions própies del gènere discursiu triat, per construir coneixement i donar resposta de manera informada, eficac i creativa a demandes comunicatives concretes. | E8: 5. Produir textos escrits i multimodals amb adequació, coherència, cohesió, aplicant estratègies elementals de planificació, redacció, revisió, correcció i edició, amb regulació dels iguals i autoregulació progressivament autónoma i atenent les convencions própies del gènere discursiu triat, per construir coneixement i donar resposta de manera informada, eficac i creativa a demandes comunicatives concretes. | G8: 5. Produir textos escrits i multimodals amb adequació, coherència i cohesió, aplicant estratègies elementals de planificació, redacció, revisió, correcció i edició, amb regulació dels iguals i autoregulació progressivament autónoma, i atenent les convencions própies del gènere discursiu triat, per construir coneixement i donar resposta de manera informada, eficac i creativa a demandes comunicatives concretes. | I8: 5. Analitzar de forma crítica els mecanismes que han regulat la vida de les societats al llarg de la història fins a l’actualitat i la construcció dels sistemes democràtics per participar de manera respectuosa i compromesa en activitats comunitàries que promoguin la convivència, la cohesió social i l’equitat. | K8: 5. Adquirir actituds, valors i habilitats socials en la pràctica d’activitat física i esportiva per a la millora de la convivència i la cohesió social. | M8: 5. Connectar diferents elements matemàtics relacionant conceptes, procediments, arguments i models per desenvolupar una visió de les matemàtiques com un tot integrat. | O8: 5. Analitzar els efectes de determinades accions sobre el medi ambient i la salut, basant-se en els fonaments de les ciències biológiques i geológiques, per fer propostes d’acció i per decidir de manera informada sobre problemàtiques actuals i adoptar hàbits que minimitzin els impactes mediambientals, que siguin compatibles amb un desenvolupament sostenible i que permetin mantenir i millorar la salut individual i col-lectiva. | Q8: 5. Analitzar els efectes de determinades accions sobre el medi ambient i la salut, basant-se en els fonaments de les ciències físiques i químiques, per fer propostes d’acció per decidir de manera informada en problemàtiques actuals i adoptar hàbits que minimitzin els impactes mediambientals, que siguin compatibles amb un desenvolupament sostenible i que permetin mantenir i millorar la salut individual i col·lectiva. | U8: 5. Explorar tècniques, mitjans i recursos dels llenguatges artístics, a través de l’experimentació i la recerca, amb perseverança i entenent l’error com una oportunitat per aprendre, per aplicar-los en el disseny i la realització d’un projecte artístic. | W8: 5. Desenvolupar algorismes i aplicacions informàtiques en diferents entorns, tot aplicant els principis del pensament computacional i incorporant les tecnologies emergents, per resoldre problemes concrets, automatitzar processos i aplicar-los en sistemes de control o robòtica. | AE8: 5. Analitzar els efectes de determinades accions sobre el medi ambient i la salut, basant-se en els fonaments de les ciències biológiques i geológiques, per fer propostes d’acció i per decidir de manera informada sobre problemàtiques actuals i adoptar hàbits que minimitzin els impactes mediambientals, que siguin compatibles amb un desenvolupament sostenible i que permetin mantenir i millorar la salut individual i col-lectiva. | AG8: 5. Analitzar l’impacte de les tecnologies digitals a la societat, a partir de la identificació dels canvis econòmics i socials a escala global, i aplicar les tecnologies emergents per al disseny de solucions a problemes reals tenint en compte els objectius de desenvolupament sostenible. | AI8: 5. Dissenyar un pla financer personal i/o familiar, aplicant estratègies de planificació i presa de decisions, avaluant-ne la coherència i consistència al llarg del temps, per donar resposta a les necessitats vitals presents i futures, i millorar la qualitat de vida. | AK8: 5. Dissenyar solucions emprenedores, creatives i sostenibles, utilitzant metodologies àgils i actives d’ideació amb sentit ètic i solidari, per donar resposta sostenible a les necessitats i demandes de la societat. | AO8: 5. Analitzar els efectes de determinades accions sobre el medi ambient i la salut, basant-se en els fonaments de les ciències físiques i químiques, per fer propostes d’acció per decidir de manera informada en problemàtiques actuals i adoptar hàbits que minimitzin els impactes mediambientals, que siguin compatibles amb un desenvolupament sostenible i que permetin mantenir i millorar la salut individual i col·lectiva. | AQ8: 5. Descobrir les pròpies competències i interessos professionals, així com les oportunitats acadèmiques i professionals de l’entorn, desenvolupant actituds d’autosuperació, adaptabilitat i iniciativa, i les destreses necessàries per a una presa de decisions ajustada al projecte vital, acadèmic i professional. | AS8: 5. Analitzar i valorar el patrimoni cultural, arqueològic i artístic romà, apreciant- lo i reconeixent-lo com a manifestació de la creació humana i com a testimoni de la història, per identificar-hi les fonts d’inspiració i distingir els processos de construcció, preservació, conservació i restauració, i garantir-ne la sostenibilitat. | AW8: 5. Produir textos escrits i multimodals amb adequació, coherència i cohesió, aplicant estratègies elementals de planificació, redacció, revisió, correcció i edició, amb regulació dels iguals i autoregulació progressivament autónoma, i atenent les convencions própies del gènere discursiu triat, per construir coneixement i donar resposta de manera informada, eficac i creativa a demandes comunicatives concretes. | AY8: 5. Emprar les eines digitals de disseny i fabricació, adaptant-les i configurant- les a les necessitats tot aplicant els coneixements interdisciplinaris, per a una producció més eficient i sostenible. | BC8: CD5. Desenvolupar aplicacions informàtiques senzilles i solucions tecnològiques creatives i sostenibles per resoldre problemes concrets o respondre a reptes proposats, i mostrar interès i curiositat per l’evolució de les tecnologies digitals i pel seu desenvolupament sostenible i ús ètic. | BD8: CPSAA 5. Planificar objectius a mitjà termini i desenvolupar processos metacognitius de retroacció per aprendre dels propis errors en el procés de construcció de coneixement.
C9: 6. Cercar, seleccionar i contrastar informació procedent de diferents fonts de manera progressivament autónoma, avaluant-ne la fiabilitat i pertinència en funció dels objectius de lectura i evitant els riscos de manipulació i desinformació, i integrar-la i transformar-la en coneixement, per comunicar- la, adoptant un punt de vista crític, personal i respectuós amb la propietat intel·lectual. | E9: 6. Cercar, seleccionar i contrastar informació procedent de diferents fonts de manera progressivament autónoma, avaluant-ne la fiabilitat i pertinència en funció dels objectius de lectura i evitant els riscos de manipulació i desinformació, i integrar-la i transformar-la en coneixement, per comunicar- la, adoptant un punt de vista crític, personal i respectuós amb la propietat intel-lectual. | G9: 6. Cercar, seleccionar i contrastar informació procedent de diferents fonts de manera progressivament autónoma, avaluant-ne la fiabilitat i pertinència en funció dels objectius de lectura i evitant els riscos de manipulació i desinformació, i integrar-la i transformar-la en coneixement, per comunicar- la, adoptant un punt de vista crític, personal i respectuós amb la propietat intel·lectual. | I9: 6. Interpretar els processos que han conformat les societats actuals en la seva diversitat i riquesa a partir de l’anàlisi de perspectives i mirades diverses per formar-se un criteri propi fonamentat i comprometre’s en la defensa dels drets humans, la llibertat i la igualtat davant les situacions d’injustícia i discriminació. | M9: 6. Vincular i contextualitzar les matemàtiques amb altres àrees de coneixement, interrelacionant conceptes i procediments, per resoldre problemes i desenvolupar la capacitat crítica, creativa i innovadora en situacions diverses. | O9: 6. Analitzar els elements del paisatge, utilitzant de forma integrada els coneixements procedents de la biologia, la geologia i les ciències ambientals per explicar-ne l’origen i la possible evolució, així com les característiques de la comunitat d’organismes, la dinàmica del relleu i els possibles riscos naturals. | Q9: 6. Interpretar i valorar la ciència com una construcció col·lectiva en continu canvi i evolució, que requereix la interacció amb la resta de la societat per generar millores que repercuteixin en l’avenc tecnològic, econòmic, ambiental i social. | U9: 6. Realitzar projectes, disciplinaris o transdisciplinaris, personals o col·lectius, a partir de situacions i establint connexions amb la realitat propera, amb implicació i compromís, per comunicar, reflexionar i resoldre problemes. | W9: 6. Utilitzar els fonaments del funcionament dels dispositius i de les aplicacions habituals de l’entorn digital d’aprenentatge, analitzant-ne els components i les funcions i ajustant-los a les necessitats per fer-ne un ús més eficient i segur, per detectar i resoldre problemes tècnics senzills. | AE9: 6. Analitzar els elements del paisatge, utilitzant de forma integrada els coneixements procedents de la biologia, la geologia i les ciències ambientals per explicar-ne l’origen i la possible evolució, així com les característiques de la comunitat d’organismes, la dinàmica del relleu i els possibles riscos naturals. | AK9: (Optativa 4t) 6. Seleccionar els recursos disponibles durant el procés de desenvolupament de la idea o solució creativa, coneixent els mitjans de producció i les fonts financeres, aplicant estratègies de tria d’aquests per posar en marxa el projecte. | AO9: 6. Interpretar i valorar la ciència com una construcció col·lectiva en continu canvi i evolució, que requereix la interacció amb la resta de la societat per generar millores que repercuteixin en l’avenc tecnològic, econòmic, ambiental i social. | AW9: 6. Cercar, seleccionar i contrastar informació procedent de diferents fonts de manera progressivament autónoma, avaluant-ne la fiabilitat i pertinència en funció dels objectius de lectura i evitant els riscos de manipulació i desinformació, i integrar-la i transformar-la en coneixement per comunicar- la, adoptant un punt de vista crític i personal al mateix temps que respectuós amb la propietat intel-lectual. | AY9: 6. Analitzar processos tecnològics, valorant l’impacte en la societat i l’entorn, tot aplicant criteris de sostenibilitat, per fer un ús ètic i ecosocialment responsable de la tecnologia.
C10: 7. Seleccionar i llegir de manera autónoma obres diverses com a font de plaer i coneixement, configurant un itinerari lector que s’enriqueixi progressivament pel que fa a diversitat, complexitat i qualitat de les obres, i compartir experiències de lectura, per construir la própia identitat lectora i gaudir de la dimensió social de la lectura. | E10: 7. Seleccionar i llegir de manera autónoma obres diverses com a font de plaer i coneixement, configurant un itinerari lector que s’enriqueixi progressivament pel que fa a diversitat, complexitat i qualitat de les obres, i compartir experiències de lectura, per construir la própia identitat lectora i gaudir de la dimensió social de la lectura. | G10: 7. Seleccionar i llegir de manera autónoma obres diverses com a font de plaer i coneixement, configurant un itinerari lector que s’enriqueixi progressivament pel que fa a diversitat, complexitat i qualitat de les obres, i compartir experiències de lectura per construir la própia identitat lectora i gaudir de la dimensió social de la lectura. | I10: 7. Identificar els fonaments que sostenen les identitats personals i col·lectives des d’una perspectiva intercultural, respectant els sentiments de pertinença, i valorar les diverses manifestacions culturals i artístiques i el patrimoni material i immaterial per contribuir a la cohesió social i als valors que emanen d’una ciutadania europea responsable i solidària. | M10: 7. Comunicar i representar, de forma individual i col·lectiva, conceptes, procediments i resultats matemàtics usant el llenguatge oral, escrit, gràfic, multimodal i la terminologia matemàtica apropiada, per donar significat i permanència a les idees matemàtiques. | W10: 7. Fer ús ètic, sostenible i ecosocialment responsable de la tecnologia, identificant les repercussions i les aportacions, per valorar l’impacte del desenvolupament tecnològic a la societat i a l’entorn. | AK10: (Optativa 4t) 7. Comunicar-se de manera efectiva i respectuosa, amb l’ús d’estratègies comunicatives diverses, tenint en compte el context i la situació per presentar, exposar i validar una idea o solució emprenedora. | AW10: 7. Seleccionar i llegir de manera autónoma obres diverses com a font de plaer i coneixement, configurant un itinerari lector que s’enriqueixi progressivament pel que fa a diversitat, complexitat i qualitat de les obres, i compartir experiències de lectura per construir la própia identitat lectora i gaudir de la dimensió social de la lectura.
C11: 8. Llegir, interpretar i valorar obres o fragments literaris del patrimoni propi i universal, utilitzant un metallenguatge específic i mobilitzant l’experiència biogràfica i els coneixements literaris i culturals, per establir vincles entre textos diversos que permetin conformar un mapa cultural, eixamplar les possibilitats de gaudir de la literatura i crear textos d’intenció literària. | E11: 8. Llegir, interpretar i valorar obres o fragments literaris del patrimoni propi i universal, utilitzant un metallenguatge específic i mobilitzant l’experiència biogràfica i els coneixements literaris i culturals, per establir vincles entre textos diversos que permetin conformar un mapa cultural, eixamplar les possibilitats de gaudir de la literatura i crear textos d’intenció literària. | G11: 8. Mediar entre diferents llengües, fent servir estratègies i coneixements senzills orientats a explicar conceptes o simplificar missatges, per transmetre informació de manera eficac, clara i responsable. | I11: 8. Analitzar les formes de vida i els fets i fenòmens socials, passats i presents, des de la perspectiva de gènere, i comprometre’s en la igualtat d’oportunitats, la participació efectiva i la responsabilitat compartida de totes les persones en la societat i l’entorn, superar estereotips i rebutjar qualsevol forma de discriminació i violència. | M11: 8. Desenvolupar destreses personals, com l’autoregulació, que ajudin a identificar i gestionar emocions, aprenent de l’error i afrontant les situacions d’incertesa com una oportunitat, per perseverar i gaudir del procés d’aprendre matemàtiques. | AK11: (Optativa 4t) 8. Valorar críticament els aspectes bàsics de l’economia i les finances en relació amb el problema de l’escassetat i la necessitat de triar, així com la interacció entre els agents econòmics, de manera eficaç, equitativa i sostenible per afrontar els reptes plantejats. | AW11: 8. Mediar entre diferents llengües, fent servir estratègies i coneixements senzills orientats a explicar conceptes o simplificar missatges, per transmetre informació de manera eficac, clara i responsable.
C12: 9. Mobilitzar el coneixement sobre l’estructura de la llengua i els seus usos i reflexionar de manera progressivament autónoma sobre les eleccions lingüístiques i discursives, amb la terminologia adequada, per desenvolupar la consciència lingüística, augmentar el repertori comunicatiu i millorar les destreses tant de producció oral i escrita com de recepció crítica. | E12: 9. Mobilitzar el coneixement sobre l’estructura de la llengua i els seus usos i reflexionar de manera progressivament autónoma sobre les eleccions lingüístiques i discursives, amb la terminologia adequada, per desenvolupar la consciència lingüística, augmentar el repertori comunicatiu i millorar les destreses tant de producció oral i escrita com de recepció crítica. | G12: 9. Ampliar i usar els repertoris lingüístics personals entre diferents llengües, reflexionant de manera crítica sobre el seu funcionament i prenent consciència de les estratègies i coneixements propis, per millorar la resposta a necessitats comunicatives concretes. | I12: 9. Valorar críticament les dinàmiques d’interdependència entre diferents factors dins un món globalitzat i les desigualtats i conflictes que es generen, i relacionar les problemàtiques locals i globals per proposar alternatives basades en la cultura de la pau i adquirir compromisos que permetin la consecució d’un món més solidari i sostenible. | M12: 9. Desenvolupar destreses socials, com la cooperació, participant activament en equips de treball inclusius reconeixent la diversitat i el valor de les aportacions dels altres, per compartir i construir coneixement de matemàtic de manera col·lectiva. | AK12: (Optativa 4t) 9. Dissenyar prototips innovadors, aplicant estratègies de planificació, gestió i presa de decisions, de manera cooperativa i autònoma, per resoldre els reptes proposats i reflexionar sobre el procés i el resultat obtingut. | AW12: 9. Ampliar i usar els repertoris lingüístics personals entre diferents llengües, reflexionant de manera crítica sobre el seu funcionament i prenent consciència de les estratègies i coneixements propis, per millorar la resposta a necessitats comunicatives concretes.
C13: 10. Posar al servei de la convivència democràtica, la resolució dialogada dels conflictes i la igualtat de drets de totes les persones, les própies pràctiques comunicatives, utilitzant un llenguatge no discriminatori i desterrant els abusos de poder a través de la paraula, per afavorir un ús eficac, ètic i democràtic del llenguatge. | E13: 10. Posar al servei de la convivència democràtica, la resolució dialogada dels conflictes i la igualtat de drets de totes les persones, les própies pràctiques comunicatives, utilitzant un llenguatge no discriminatori i desterrant els abusos de poder a través de la paraula, per afavorir un ús eficac, ètic i democràtic del llenguatge. | G13: 10. Posar al servei de la convivència democràtica, la resolució dialogada dels conflictes i la igualtat de drets de totes les persones, les própies pràctiques comunicatives, utilitzant un llenguatge no discriminatori i desterrant els abusos de poder a través de la paraula, per afavorir un ús eficac, ètic i democràtic del llenguatge. | AK13: (Optativa 4t) 10. Analitzar la viabilitat i sostenibilitat dels prototips creats, avaluant les fases del procés d’elaboració, de manera crítica i ètica, considerant l’experiència com una oportunitat per a la millora d’aquests i per a l’aprenentatge. | AW13: 10. Posar al servei de la convivència democràtica, la resolució dialogada dels conflictes i la igualtat de drets de totes les persones, les própies pràctiques comunicatives, utilitzant un llenguatge no discriminatori i desterrant els abusos de poder a través de la paraula per afavorir un ús no només eficac sinó també ètic i democràtic del llenguatge.

Sheet MATÈRIES OCULT
B3: OBLIGATÒRIES | G3: OPTATIVES
B5: 1r ESO | C5: 2n ESO | D5: 3r ESO | E5: 4t ESO | G5: 1r ESO | H5: 2n ESO | I5: 3r ESO | J5: 4t ESO
B6: Llengua Catalana i Literatura | C6: Llengua Catalana i Literatura | D6: Llengua Catalana i Literatura | E6: Llengua Catalana i Literatura | G6: Emprenedoria | H6: Emprenedoria | I6: Emprenedoria | J6: Emprenedoria
B7: Llengua Castellana i Literatura | C7: Llengua Castellana i Literatura | D7: Llengua Castellana i Literatura | E7: Llengua Castellana i Literatura | G7: Robòtica i Programació | H7: Robòtica i Programació | I7: Robòtica i Programació | J7: Biologia i Geologia
B8: Llengua Estrangera | C8: Llengua Estrangera | D8: Llengua Estrangera | E8: Llengua Estrangera | G8: Cultura Clàssica | H8: Cultura Clàssica | I8: Cultura Clàssica | J8: Cultura Clàssica
B9: Matemàtiques | C9: Matemàtiques | D9: Matemàtiques | E9: Matemàtiques | G9: Segona Llengua Estrangera | H9: Segona Llengua Estrangera | I9: Segona Llengua Estrangera | J9: Digitalització
B10: Ciències Socials: Geografia i Història | C10: Ciències Socials: Geografia i Història | D10: Ciències Socials: Geografia i Història | E10: Ciències Socials: Geografia i Història | J10: Segona Llengua Estrangera
B11: Biologia i Geologia | C11: Biologia i Geologia | D11: Biologia i Geologia | E11: Educació en Valors Cívics i Ètics | J11: Física i Química
B12: Física i Química | C12: Física i Química | D12: Física i Química | E12: Educació Física | J12: Filosofia
B13: Tecnologia i Digitalització | C13: Tecnologia i Digitalització | D13: Tecnologia i Digitalització | J13: Arts Escèniques i Dansa
B14: Educació Plàstica, Visual i Audiovisual | C14: Educació Plàstica, Visual i Audiovisual | D14: Educació Plàstica, Visual i Audiovisual | J14: Formació i Orientació Personal i Professional
B15: Música | C15: Música | D15: Música | J15: Llatí: Llengua i Cultura
B16: Educació Física | C16: Educació Física | D16: Educació Física | J16: Música
J17: Tecnologia
J18: Expressió Artística
J19: Economia Bàsica
B24: FILTRE OBLIGATÒRIES | G24: FILTRE OPTATIVES
B26: =IFERROR(__xludf.DUMMYFUNCTION("FILTER(B5:E16,B5:E5=INICI!C5)"),"4t ESO") -> 4t ESO | G26: =IFERROR(__xludf.DUMMYFUNCTION("FILTER(G5:J19,G5:J5=INICI!C5)"),"4t ESO") -> 4t ESO
B27: =IFERROR(__xludf.DUMMYFUNCTION("""COMPUTED_VALUE"""),"Llengua Catalana i Literatura") -> Llengua Catalana i Literatura | G27: =IFERROR(__xludf.DUMMYFUNCTION("""COMPUTED_VALUE"""),"Emprenedoria") -> Emprenedoria
B28: =IFERROR(__xludf.DUMMYFUNCTION("""COMPUTED_VALUE"""),"Llengua Castellana i Literatura") -> Llengua Castellana i Literatura | G28: =IFERROR(__xludf.DUMMYFUNCTION("""COMPUTED_VALUE"""),"Biologia i Geologia") -> Biologia i Geologia
B29: =IFERROR(__xludf.DUMMYFUNCTION("""COMPUTED_VALUE"""),"Llengua Estrangera") -> Llengua Estrangera | G29: =IFERROR(__xludf.DUMMYFUNCTION("""COMPUTED_VALUE"""),"Cultura Clàssica") -> Cultura Clàssica
B30: =IFERROR(__xludf.DUMMYFUNCTION("""COMPUTED_VALUE"""),"Matemàtiques") -> Matemàtiques | G30: =IFERROR(__xludf.DUMMYFUNCTION("""COMPUTED_VALUE"""),"Digitalització") -> Digitalització
B31: =IFERROR(__xludf.DUMMYFUNCTION("""COMPUTED_VALUE"""),"Ciències Socials: Geografia i Història") -> Ciències Socials: Geografia i Història | G31: =IFERROR(__xludf.DUMMYFUNCTION("""COMPUTED_VALUE"""),"Segona Llengua Estrangera") -> Segona Llengua Estrangera
B32: =IFERROR(__xludf.DUMMYFUNCTION("""COMPUTED_VALUE"""),"Educació en Valors Cívics i Ètics") -> Educació en Valors Cívics i Ètics | G32: =IFERROR(__xludf.DUMMYFUNCTION("""COMPUTED_VALUE"""),"Física i Química") -> Física i Química
B33: =IFERROR(__xludf.DUMMYFUNCTION("""COMPUTED_VALUE"""),"Educació Física") -> Educació Física | G33: =IFERROR(__xludf.DUMMYFUNCTION("""COMPUTED_VALUE"""),"Filosofia") -> Filosofia
G34: =IFERROR(__xludf.DUMMYFUNCTION("""COMPUTED_VALUE"""),"Arts Escèniques i Dansa") -> Arts Escèniques i Dansa
G35: =IFERROR(__xludf.DUMMYFUNCTION("""COMPUTED_VALUE"""),"Formació i Orientació Personal i Professional") -> Formació i Orientació Personal i Professional
G36: =IFERROR(__xludf.DUMMYFUNCTION("""COMPUTED_VALUE"""),"Llatí: Llengua i Cultura") -> Llatí: Llengua i Cultura
G37: =IFERROR(__xludf.DUMMYFUNCTION("""COMPUTED_VALUE"""),"Música") -> Música
G38: =IFERROR(__xludf.DUMMYFUNCTION("""COMPUTED_VALUE"""),"Tecnologia") -> Tecnologia
G39: =IFERROR(__xludf.DUMMYFUNCTION("""COMPUTED_VALUE"""),"Expressió Artística") -> Expressió Artística
G40: =IFERROR(__xludf.DUMMYFUNCTION("""COMPUTED_VALUE"""),"Economia Bàsica") -> Economia Bàsica

Sheet CURS OCULT
F3: Aquí sota hi ha el filtre de curs
B5: Primer cicle | C5: Segon cicle | F5: =IFERROR(__xludf.DUMMYFUNCTION("filter(B5:C8,B5:C5=INICI!C4)"),"Segon cicle") -> Segon cicle
B6: 1r ESO | C6: 4t ESO | F6: =IFERROR(__xludf.DUMMYFUNCTION("""COMPUTED_VALUE"""),"4t ESO") -> 4t ESO
B7: 2n ESO
B8: 3r ESO
F14: Aquí filtre per optatives
B16: 1r ESO | C16: 2n ESO | D16: 3r ESO | E16: 4t ESO | G16: =IFERROR(__xludf.DUMMYFUNCTION("filter(B16:E17,B16:E16=INICI!C5)"),"4t ESO") -> 4t ESO
B17: 1r, 2n i 3r | C17: 1r, 2n i 3r | D17: 1r, 2n i 3r | E17: 4t | G17: =IFERROR(__xludf.DUMMYFUNCTION("""COMPUTED_VALUE"""),"4t") -> 4t

Sheet FILTRE COMPETÈNCIES
B2: 1 | C2: =IFERROR(__xludf.DUMMYFUNCTION("filter('COMPETÈNCIES OCULT'!C3:AY13,'COMPETÈNCIES OCULT'!C3:AY3='COMPETÈNCIES'!B4)"),"Llengua Estrangera") -> Llengua Estrangera
